Workbook
Name logo: 'UT3'!$A$1:$C$2
Name logo: 'UT11'!$A$1:$C$2
Name logo: 'UT8'!$A$1:$C$2
Name logo: 'UT1'!$A$1:$C$2
Name logo: 'UT5'!$A$1:$C$2
Name logo: 'UT9'!$A$1:$C$2
Name logo: 'UT12'!$A$1:$C$2
Name logo: 'UT10'!$A$1:$C$2
Name logo: 'UT6'!$A$1:$C$2
Name logo: 'UT7'!$A$1:$C$2
Name logo: 'UT4'!$A$1:$C$2
Name logo: 'UT2'!$A$1:$C$2

Sheet 0-PORTADA
H1: CIFP PAU CASESNOVES
A20: MDO20201
A21: Per emplenar aquest model de programació heu d'emplenar totes les fulles d'aquest document en l'ordre estabert (full 1, full2...).
A22: Fixau-vos que: - Emplenant el full 6-Distribució temporal, s'emplena automàticament la capçalera del corresponent full UTx. - Emplenant el darrer apartat de cada full UTx d'observacions per introduir a la memòria, s'emplena automàticament l'apartat corresponent del darrer full de MEMÒRIA FI DE CURS. - El primer apartat del darrer full de MEMÒRIA FI DE CURS d'aspectes generals s'ha d'emplenar manualment. - Es poden afegir línies de text a la mateixa cel·la fent servir la combinació de tecles CTRL-INTRO.

Sheet 1-INTRODUCCIÓ
A2: CURS 26/27 - INTRODUCCIÓ
A3: REAL DECRET QUE REGULA EL TÍTOL | B3: RD 686/2010, de 20 de maig, modificat per el RD 405/2023
A4: CICLE | B4: Desenvolupament d'aplicacions web | G4: NIVELL | H4: GS
A5: MÒDUL | B5: Desenvolupament web en entorn servidor | G5: CURS | H5: 2n
A6: PROFESSOR/RA | B6: David Rafael Pons Servera
A7: HORES DEL MÒDUL | B7: TOTALS | C7: 230 | E7: SETMANALS | F7: 7
A8: UNITATS DE COMPETÈNCIA TREBALLADES AL MÒDUL
A9: Completes: a1) Desenvolupament d'aplicacions amb tecnologia Web IFC154_3 (Real Decret 1087/2005, de 16 de setembre): UC0492_3 Desenvolupar elements software en entorn servidor. UC0493_3 Implementar, verificar i documentar aplicacions web en entorns internet, intranet i extranet. Incompletes: b1) Programació en llenguatges estructurats d'aplicacions de gestió IFC155_3 (Real Decret 1087/2005, de 16 de setembre) UC0226_3 Programar bases de dades relacionals. b2) Programació amb llenguatges orientats a objectes i bases de dades relacionals IFC 080_3 (Real Decret. 295/2004, de 20 de febrer). UC0226_3 Programar bases de dades relacionals.
A10: OBJECTIUS GENERALS DEL CICLE ALS QUE CONTRIBUEIX LA FORMACIÓ DEL MÒDUL
A11: 1- Instal·lar mòduls analitzant la seva estructura i funcionalitat per a gestionar servidors d'aplicacions 2- Ajustar paràmetres analitzant la configuració per a gestionar servidors d'aplicacions 3- Seleccionar llenguatges, objectes i eines, interpretant les especificacions per a desenvolupar aplicacions web amb accés a bases de dades 4- Utilitzar llenguatges, objectes i eines, interpretant les especificacions per a desenvolupar aplicacions web amb accés a bases de dades 5- Generar components d'accés a dades, complint les especificacions, per a integrar continguts en la lògica d'una aplicació web 6- Utilitzar eines i llenguatges específics, complint les especificacions, per a desenvolupar i integrar component programari a l'entorn del servidor web 7- Emprar eines específiques, integrant la funcionalitat entre aplicacions, per a desenvolupar serveis ocupables en aplicacions web 8- Avaluar serveis distribuïts ja desenvolupats, verificant les seves prestacions i funcionalitat, per a integrar serveis distribuïts en una aplicació web 9- Verificar els components de programari desenvolupat, analitzant les especificacions, per a completar el pla de proves 10- Programar i realitzar activitats per a gestionar el manteniment dels recursos informàtics. 11- Desenvolupar la creativitat i l'esperit d'innovació per a respondre als reptes que es presenten en els processos i organització de treball i de la vida personal 12- Prendre decisions de forma fonamentada analitzant les variables implicades, integrant sabers de diferent àmbit i acceptant els riscos i la possibilitat d'equivocació en aquestes, per a afrontar i resoldre diferents situacions, problemes o contingències.
A12: COMPETÈNCIES DEL CICLE A LES QUE CONTRIBUEIX LA FORMACIÓ DEL MÒDUL
A13: Desenvolupar, implantar, i mantenir aplicacions web, amb independència del model empleat i utilitzant tecnologies específiques, garantint l'accés a les dades de forma segura i complint els criteris d'accessibilitat, usabilitat i qualitat exigits en els estàndards establerts.

Sheet 2-ANCORATGE CURRICULAR
A3: RA/CP/CS | B3: RESULTAT D'APRENENTATGE/COMPETÈNCIA PERSONAL/COMPETÈNCIA SOCIAL | C3: % Pes RA total | D3: % RA en empresa (entre 10% i 20%) | E3: % RA al centre | F3: UTs on es treballa
A4: RA1 | B4: Selecciona les arquitectures i tecnologies de programació Web en entorn servidor, analitzant les seves capacitats i característiques pròpies | C4: 5 | E4: =100-D4 -> 100 | F4: 1
A5: RA2 | B5: Escriu sentències executables per un servidor Web reconeixent i aplicant procediments de integració del codi en llenguatges de marques. | C5: 10 | E5: =100-D5 -> 100 | F5: 4
A6: RA3 | B6: Escriu blocs de sentències embeguts en llenguatges de marques, seleccionant i utilitzant les estructures de programació | C6: 10 | E6: =100-D6 -> 100 | F6: 4
A7: RA4 | B7: Desenvolupa aplicacions Web embegudes en llenguatges de marques analitzant i incorporant funcionalitats segons especificacions. | C7: 10 | E7: =100-D7 -> 100 | F7: 4
A8: RA5 | B8: Desenvolupa aplicacions Web identificant i aplicant mecanismes per a separar el codi de presentació de la lògica de negoci. | C8: 10 | E8: =100-D8 -> 100 | F8: 4
A9: RA6 | B9: Desenvolupa aplicacions d’accés a magatzems de dades, aplicant mesures per a mantenir la seguretat i la integritat de la informació. | C9: 20 | E9: =100-D9 -> 100 | F9: 2
A10: RA7 | B10: Desenvolupa serveis Web reutilitzables i accessibles mitjançant protocols web, verificant el seu funcionament. | C10: 20 | D10: 10 | E10: =100-D10 -> 90 | F10: 3
A11: RA8 | B11: Genera pàgines Web dinàmiques analitzant i utilitzant tecnologies del servidor Web que afegeixin codi al llenguatge de marques | C11: 10 | E11: =100-D11 -> 100 | F11: 4
A12: RA9 | B12: Desenvolupa aplicacions Web híbrides seleccionant i utilitzant llibreries de codi i repositoris heterogenis de informació | C12: 5 | D12: 10 | E12: =100-D12 -> 90 | F12: 3
A13: CP | B13: Descripció de la competència personal | C13: 0 | E13: =100-D13 -> 100
A14: CS | B14: Descripció de la competència social | C14: 0 | E14: =100-D14 -> 100
B15: TOTAL (ha de sumar un 100%): | C15: =SUM(C4:C14) -> 100
A17: Fixau-vos que: - El % de RA en empresa ha de ser el que s'ha consensuat al pla de formació FEMPO del cicle i ha de coindicir. - Les caselles sombrejades en gris fort es calculen automàticament.

Sheet 3-METODOLOGIA
A2: METODOLOGIA
A3: Metodologia didàctica aplicada a l’aula
A4: La metodologia serà durant tot el curs dinàmica, oberta i flexible, adaptant-se al context de situació tan dels alumnes com del centre i tenint en compte l’entorn que el rodeja. A més, es fonamentarà en els principis i teories que integren els enfocaments constructivista i funcional de l’aprenentatge. - Exposicions dels continguts a classe. - Exercicis per treballar els continguts exposats (activitats a classe, qüestionaris, informes, recerca, tasca a casa...). - Pràctiques individuals o en grup amb el programari més emprat del mercat o el que es consideri més didàctic. - Treballs d’investigació realitzats en grup o bé individualment sobre programari del que no es disposi o no sigui factible implementar dins l’aula. - Observació dins l’aula. - Pràctica globalitzadora (projecte) de simulació d'una empresa del sector comercial o productiu. L’intercanvi de documentació professor/alumne es farà bàsicament a través de l’aula virtual de tal manera que tota la informació, apunts, pàgines web, fòrums, lliurament i correcció de pràctiques i treballs, etc. serà a través d’aquest mitjà. També es faran servir les eines del GSuite corporatiu. El lliurament per part de l’alumne de les pràctiques i treballs es realitza a través de l’aula virtual.
A5: Material, recursos, roba corporativa i equips de protecció individual (EPIs)
A6: Materials i exercicis de desenvolupament pròpi. Moodle. Github Classrom. Java IDE: VSC, IntelliJ, Netbeans, eclipse, ... el que vulgui l'alumne.
A7: Atenció a la diversitat
A8: Es tendran en comptes les pautes indicades pel departament d'orientació en cada un dels casos concrets.

Sheet 4-AVALUACIÓ
A2: AVALUACIÓ I QUALIFICACIÓ DEL MÒDUL PROFESSIONAL
A3: Com s'avaluarà
A4: - Per a poder superar el mòdul professional, han d'haver-se superat tots els resultats d'aprenentatge. Es considera la superació d'un mòdul quan la seva qualificació és igual o superior a 5 punts. - Hi haurà 3 avaluacions on es treballaran els resultats d’aprenentatge definits al real decret segon l’establert a la distribució temporal. - Cada mòdul té una convocatòria ordinària i una extraordinària per curs escolar. - Com a mecanismes d'avaluació s'empraran pràctiques, projectes, exposicions, exàmens escrits, defensa oral, observació diària, etc.
A5: Criteris de qualificació (com es qualificaran les diferents activitats, proves... i com s'obtindrà la qualificació final)
A6: El Decret 39/2025, d’1 d’agost, d’ordenació de la formació professional a les Illes Balears, en el seu article 18 estableix el següent: - La qualificació dels mòduls professionals i, en el seu cas, del projecte estarà en funció de la consecució dels resultats d’aprenenetatge i serà numèrica, entre u i deu, sense decimals. - Es consideren positives les puntuacions dels mòduls professionals qualificades amb igual o superior a cinc punts. - Cada RA té el pes establert a l’ancoratge curricular i la seva qualificació resulta de les activitats d’avaluació que hi estan associades. Cada RA s’ha de superar amb una qualificació mínima de 5. Una qualificació inferior a 5 en un RA no s’arrodoneix a 5. - Una vegada superats tots els RA, s’aplica l’arrodoniment natural per obtenir la qualificació final del mòdul, que s’expressa sense decimals. - Si el dia de la prova l’alumne no es presenta, es qualificarà amb un 0 sempre i quan no es justifiqui l’absència dins el termini establert per el centre i el motiu de la falta estigui contemplat com a justificada. - En cas que per manca de temps sigui impossible veure un RA el pes que té associat s'assignarà proporcionalment a la resta de RA avaluats. - Plagi/còpia:La qualificació obtinguda serà de 0. - Ús d’IA generativa: només es permet quan el professorat l’autoritzi expressament per a una activitat concreta i en les condicions que indiqui. Quan se n’autoritzi l’ús, aquest ha de ser traçable. Per aprovar el resultat d'aprenentatge és indispensable cada un d’aquests requisits: - Haver lliurat totes les pràctiques i treballs definits com a obligatoris i haver obtingut una qualificació d'aprovat. - Tenir la mitjana de les proves específiques individuals aprovades amb un 5. Cada prova es puntuarà d'1 a 10. Per poder fer mitjana una prova ha de tenir com a mínim un 5. - Les proves individuals específiques suspeses es podran recuperar mitjançant una prova final a final de curs. La nota màxima d'aquestes proves de recuperació serà un 5. - Pràctiques i treballs: Les pràctiques, exercicis i treballs tindran la finalitat de preparació per a l'examen, no tenint ponderació a la nota.
A7: Com es podrà recuperar el mòdul durant el curs?
A8: Es podran recuperar les activitats associades als resultats d'aprenentatge no superats mitjançant els procediments que el professor consideri necessaris i que serveixin per a comprovar l’adquisició dels mateixos. Els exàmens no superats es recuperaran a final de curs. Els alumnes que puguin accedir a les proves extraordinàries, podran recuperar el mòdul o competències no assolides segons els continguts i criteris establerts al full de recuperació de pendents lliurat a l’alumne juntament amb les notes de l’avaluació ordinària, on s’indicarà a l’alumne que ha recuperar i si ha de lliurar alguna activitat per poder realitzar la prova final. Els criteris d’avaluació seran, en qualsevol cas, els mateixos que els quals es segueixen en les avaluacions ordinàries.
A9: Avaluació de pendents (com ha de recuperar el mòdul l'alumnat que el té pendent)
A10: Es farà seguint els continguts i criteris establerts al full de recuperació de pendents lliurat a l’alumne, MDO20408 MODEL FULL DE RECUPERACIÓ DE PENDENTS.

Sheet 5-Activitats extraescolars
A2: ACTIVITATS COMPLEMENTÀRIES I EXTRAESCOLARS
A3: Si és possible es realitzarà una activitat complementària de visita a una empresa del sector i/o events relacionats amb els continguts treballats al cicle.

Sheet 6-Distribució temporal
A2: INTRODUIR LES UNITATS DE TREBALL
A3: UNITATS DE TREBALL | B3: CRONOGRAMA | L3: HORES
B4: SET | C4: OCT | D4: NOV | E4: DES | F4: GEN | G4: FEB | H4: MAR | I4: ABR | J4: MAI | K4: JUN
A5: 1- Introducció a la programació en entorn servidor | B5: x | L5: 20
A6: 2- Accés a dades. | B6: x | C6: x | L6: 40
A7: 3- Serveis web | C7: x | D7: x | E7: x | L7: 50
A8: 4- Aplicacions web | E8: x | F8: x | G8: x | H8: x | L8: 120
A9: 5-
A10: 6-
A11: 7-
A12: 8-
A13: 9-
A14: 10-
A15: 11-
A16: 12-
A17: HORES FEMPO DEL MÒDUL
A18: HORES TOTALS DEL MÒDUL: | B18: =SUM(L5:L16) -> 230

Sheet UT1
A2: EMPLENAR CADA UNITAT DE TREBALL A UNA FULLA DIFERENT
A3: Unitat Treball | B3: ='6-Distribució temporal'!$A5 -> 1- Introducció a la programació en entorn servidor | C3: HORES | D3: ='6-Distribució temporal'!$L5 -> 20
A4: Criteris d'avaluació | C4: Continguts
A5: RA (RA1,...) | B5: Criteris d’avaluació | C5: Selecció d'arquitectures i eines de programació: − Models d'execució de codi en entorns client/servidor. − Generació dinàmica de pàgines web. − Llenguatges de programació i tecnologies associades en entorn servidor. − Integració amb els llenguatges de marques. − Integració amb els servidors web. − Eines i frameworks de programació. en entorn servidor.
A6: RA1 | B6: a) S'han caracteritzat i diferenciat els models d'execució de codi en el servidor i en el client Web.
A7: =IFERROR(VLOOKUP(B7,'4-CA'!$A$4:$B$105,2,FALSE),"") | B7: b) S'han reconegut els avantatges que proporciona la generació dinàmica de pàgines.
A8: =IFERROR(VLOOKUP(B8,'4-CA'!$A$4:$B$105,2,FALSE),"") | B8: c) S’han identificat els mecanismes d’execució de codi en els servidors Web
A9: =IFERROR(VLOOKUP(B9,'4-CA'!$A$4:$B$105,2,FALSE),"") | B9: d) S'han reconegut les funcionalitats que aporten els servidors d'aplicacions i la seva integració amb els servidors Web.
A10: =IFERROR(VLOOKUP(B10,'4-CA'!$A$4:$B$105,2,FALSE),"") | B10: e) S’han identificat i caracteritzat els principals llenguatges i tecnologies relacionats amb la programació Web en entorn servidor
A11: =IFERROR(VLOOKUP(B11,'4-CA'!$A$4:$B$105,2,FALSE),"") | B11: f) S’han verificat els mecanismes d’integració dels llenguatges de marques amb els llenguatges de programació en entorn servidor
A12: =IFERROR(VLOOKUP(B12,'4-CA'!$A$4:$B$105,2,FALSE),"") | B12: g) S'han reconegut i avaluat les eines i frameworks de programació en entorn servidor
A13: =IFERROR(VLOOKUP(B13,'4-CA'!$A$4:$B$105,2,FALSE),"")
A14: =IFERROR(VLOOKUP(B14,'4-CA'!$A$4:$B$105,2,FALSE),"")
A15: Activitats d’ensenyament-aprenentatge (treballs, proves teòriques, proves pràctiques, exposicions, tasques...)
A16: Data | B16: Activitat | C16: Instrument avaluació * | D16: Seguiment**
A29: Observacions per introduir a la memòria final de curs (darrer full del document)
A30: Modificacions que consideres pel curs vinent, incidències, canvi del material i recursos didàctics emprats, millorar la coordinació amb altres mòduls, valoració dels criteris de qualificació, comportament del grup ...
A38: Fixau-vos que: - El títol de la Unitat de Treball i les hores s'emplenen automàticament de les dades introduïdes al full 6-Distribució temporal. - A l'apartat d'activitats d'ensenyament-aprenentatge: - Instrument d'avaluació*: pot ser una prova escrita, una rúbrica, una prova oral, un qüestionari, una pràctica, un treball... - Seguiment**: només s'ha d'emplenar si es fa servir el document com a QUADERN de professor, en tal cas, s'anotaran les incidències/observacions que es considerin oportunes.

Sheet UT2
A2: EMPLENAR CADA UNITAT DE TREBALL A UNA FULLA DIFERENT
A3: Unitat Treball | B3: ='6-Distribució temporal'!$A6 -> 2- Accés a dades. | C3: HORES | D3: ='6-Distribució temporal'!$L6 -> 40
A4: Criteris d'avaluació | C4: Continguts
A5: RA (RA1,...) | B5: Criteris d’avaluació | C5: Utilització de tècniques daccés a dades: − Establiment de connexions. − Recuperació i edició d'informació. − Utilització de conjunts de resultats. − Actualització i eliminació d'informació provinent d'una base de dades. − Utilització d'altres orígens de dades. − Prova i documentació.
A6: RA6 | B6: a) S'han analitzat les tecnologies que permeten l'accés mitjançant programació a la informació disponible a magatzems de dades.
A7: =IFERROR(VLOOKUP(B7,'4-CA'!$A$4:$B$105,2,FALSE),"") | B7: b) S'han creat aplicacions que estableixin connexions amb bases de dades.
A8: =IFERROR(VLOOKUP(B8,'4-CA'!$A$4:$B$105,2,FALSE),"") | B8: c) S'ha recuperat informació emmagatzemada a bases de dades.
A9: =IFERROR(VLOOKUP(B9,'4-CA'!$A$4:$B$105,2,FALSE),"") | B9: d) S'ha publicat en aplicacions web la informació recuperada.
A10: =IFERROR(VLOOKUP(B10,'4-CA'!$A$4:$B$105,2,FALSE),"") | B10: e) S'han utilitzat conjunts de dades per emmagatzemar la informació.
A11: =IFERROR(VLOOKUP(B11,'4-CA'!$A$4:$B$105,2,FALSE),"") | B11: f) S'han creat aplicacions web que permetin l'actualització i la eliminació dinformació disponible en una base de dades.
A12: =IFERROR(VLOOKUP(B12,'4-CA'!$A$4:$B$105,2,FALSE),"") | B12: g) S'han provat i documentat les aplicacions web.
A13: =IFERROR(VLOOKUP(B13,'4-CA'!$A$4:$B$105,2,FALSE),"")
A14: =IFERROR(VLOOKUP(B14,'4-CA'!$A$4:$B$105,2,FALSE),"")
A15: Activitats d’ensenyament-aprenentatge (treballs, proves teòriques, proves pràctiques, exposicions, tasques...)
A16: Data | B16: Activitat | C16: Instrument avaluació * | D16: Seguiment**
A29: Observacions per introduir a la memòria final de curs (darrer full del document)
A30: Modificacions que consideres pel curs vinent, incidències, canvi del material i recursos didàctics emprats, millorar la coordinació amb altres mòduls, valoració dels criteris de qualificació, comportament del grup ...
A38: Fixau-vos que: - El títol de la Unitat de Treball i les hores s'emplenen automàticament de les dades introduïdes al full 6-Distribució temporal. - A l'apartat d'activitats d'ensenyament-aprenentatge: - Instrument d'avaluació*: pot ser una prova escrita, una rúbrica, una prova oral, un qüestionari, una pràctica, un treball... - Seguiment**: només s'ha d'emplenar si es fa servir el document com a QUADERN de professor, en tal cas, s'anotaran les incidències/observacions que es considerin oportunes.

Sheet UT3
A2: EMPLENAR CADA UNITAT DE TREBALL A UNA FULLA DIFERENT
A3: Unitat Treball | B3: ='6-Distribució temporal'!$A7 -> 3- Serveis web | C3: HORES | D3: ='6-Distribució temporal'!$L7 -> 50
A4: Criteris d'avaluació | C4: Continguts
A5: RA (RA1,...) | B5: Criteris d’avaluació | C5: Programació de serveis web: − Tecnologies i protocols implicats. − Estàndards i arquitectures actuals. Formats dintercanvi de dades. − Generació d'un servei web. − Interfície d'un servei web. − Consum d'un servei web. Eines de prova. − Frameworks de documentació. Desenvolupament d'aplicacions web híbrides: − Tecnologies i frameworks. − Reutilització de codi i informació. − Utilització d'informació provinent de repositoris. − Incorporació de funcionalitats específiques. − Utilització de llibreries de codi relacionades amb Big Data i intel·ligència de negocis. Extracció, procés i anàlisi de dades provinents de repositoris. − Prova, depuració i documentació.
A6: RA7 | B6: a) S'han reconegut les característiques pròpies i l'àmbit d'aplicació de els serveis web.
A7: =IFERROR(VLOOKUP(B7,'4-CA'!$A$4:$B$105,2,FALSE),"") | B7: b) S'han reconegut els avantatges d'utilitzar serveis web per proporcionar accés a funcionalitats incorporades a la lògica de negoci duna aplicació.
A8: =IFERROR(VLOOKUP(B8,'4-CA'!$A$4:$B$105,2,FALSE),"") | B8: c) S'han identificat les tecnologies i els protocols implicats en el consum de serveis web.
A9: =IFERROR(VLOOKUP(B9,'4-CA'!$A$4:$B$105,2,FALSE),"") | B9: d) S'han utilitzat els estàndards i arquitectures més difosos i implicats en el desenvolupament de serveis web.
A10: =IFERROR(VLOOKUP(B10,'4-CA'!$A$4:$B$105,2,FALSE),"") | B10: e) S'ha programat un servei web.
A11: =IFERROR(VLOOKUP(B11,'4-CA'!$A$4:$B$105,2,FALSE),"") | B11: f) S'ha verificat el funcionament del servei web.
A12: =IFERROR(VLOOKUP(B12,'4-CA'!$A$4:$B$105,2,FALSE),"") | B12: g) S'ha consumit el servei web.
A13: =IFERROR(VLOOKUP(B13,'4-CA'!$A$4:$B$105,2,FALSE),"") | B13: h) S'ha documentat un servei web.
A14: RA9 | B14: a) S'han reconegut els avantatges que proporciona la reutilització de codi il´aprofitament d´informació ja existent.
B15: b) S'han identificat tecnologies i frameworks aplicables a la creació de aplicacions web híbrides.
B16: c) S'ha creat una aplicació web que recuperi i processi repositoris de informació ja existents.
B17: d) S'han creat repositoris específics a partir d'informació existent a magatzems dinformació.
B18: e) S'han utilitzat llibreries de codi i frameworks per incorporar funcionalitats específiques a una aplicació web.
B19: f) S'han programat serveis i aplicacions web utilitzant com a base informació i codi generats per tercers.
B20: g) S'han analitzat i utilitzat llibreries de codi relacionades amb Big Data i intel·ligència de negocis, per incorporar anàlisi i intel·ligència de dades provinent de repositoris.
B21: h) S'han provat, depurat i documentat les aplicacions generades.
A23: Activitats d’ensenyament-aprenentatge (treballs, proves teòriques, proves pràctiques, exposicions, tasques...)
A24: Data | B24: Activitat | C24: Instrument avaluació * | D24: Seguiment**
A37: Observacions per introduir a la memòria final de curs (darrer full del document)
A38: Modificacions que consideres pel curs vinent, incidències, canvi del material i recursos didàctics emprats, millorar la coordinació amb altres mòduls, valoració dels criteris de qualificació, comportament del grup ...
A46: Fixau-vos que: - El títol de la Unitat de Treball i les hores s'emplenen automàticament de les dades introduïdes al full 6-Distribució temporal. - A l'apartat d'activitats d'ensenyament-aprenentatge: - Instrument d'avaluació*: pot ser una prova escrita, una rúbrica, una prova oral, un qüestionari, una pràctica, un treball... - Seguiment**: només s'ha d'emplenar si es fa servir el document com a QUADERN de professor, en tal cas, s'anotaran les incidències/observacions que es considerin oportunes.

Sheet UT4
A2: EMPLENAR CADA UNITAT DE TREBALL A UNA FULLA DIFERENT
A3: Unitat Treball | B3: ='6-Distribució temporal'!$A8 -> 4- Aplicacions web | C3: HORES | D3: ='6-Distribució temporal'!$L8 -> 120
A4: Criteris d'avaluació | C4: Continguts
A5: RA (RA1,...) | B5: Criteris d’avaluació | C5: Inserció de codi a pàgines web: − Tecnologies associades. − Obtenció del llenguatge de marques per mostrar al client. − Etiquetes per a inserció de codi. − Tipus de dades. Conversions entre tipus de dades. − Variables. Operadors. Àmbits dutilització. Programació basada en llenguatges de marques amb codi embegut: − Preses de decisió. − Bucles. − Matrius (arrays). − Tipus de dades compostes. − Funcions. − Recuperació i utilització d'informació provinent del client web. − Processament de la informació introduïda en un formulari. − Comentaris. Desenvolupament d'aplicacions web utilitzant codi embegut: − Manteniment de l'estat. − Emmagatzematge i recuperació d'informació al client web. − Seguretat: usuaris, perfils, rols. − Autentificació d'usuaris. − Proves i depuració. Generació dinàmica de pàgines web: − Mecanismes de separació de la lògica de negoci. Frameworks web servidor. − Controls de servidor. − Mecanismes de generació dinàmica de la interfície web. − Programació orientada a objectes. Patrons de disseny. − Prova i documentació del codi. Generació dinàmica de pàgines web interactives: − Tecnologies i frameworks. − Generació dinàmica de pàgines interactives. − Obtenció remota d'informació. − Modificació de l'estructura i el contingut de la pàgina web.
A6: RA2 | B6: a) S'han reconegut els mecanismes de generació de pàgines web a partir de llenguatges de marques amb codi embegut.
B7: b) S'han identificat les principals tecnologies associades.
B8: c) S'han utilitzat etiquetes per a la inclusió de codi en el llenguatge de marques.
B9: d) S'ha reconegut la sintaxi del llenguatge de programació que s'ha de utilitzar.
B10: e) S'han escrit sentències simples i se n'han comprovat els efectes en el document resultant.
B11: f) S'han utilitzat directives per modificar el comportament predeterminat.
B12: g) S'han utilitzat els diferents tipus de variables i operadors disponibles en el llenguatge.
B13: h) Shan identificat els àmbits dutilització de les variables.
A14: RA3 | B14: a) S'han utilitzat mecanismes de decisió en la creació de blocs de sentències.
B15: b) S'han utilitzat bucles i se n'ha verificat el funcionament.
B16: c) S'han utilitzat matrius (arrays) per emmagatzemar i recuperar conjunts de dades.
B17: d) S'han creat i utilitzat funcions.
B18: e) S'han utilitzat formularis web per interactuar amb l'usuari del navegador web.
B19: f) S'han emprat mètodes per recuperar la informació introduïda al formulari.
B20: g) S'han afegit comentaris al codi.
A21: RA4 | B21: a) S'han identificat els mecanismes disponibles per al manteniment de la informació que concerneix a un client web concret i se n'han assenyalat els avantatges.
B22: b) S'han utilitzat mecanismes per mantenir l'estat de les aplicacions web.
B23: c) S'han utilitzat mecanismes per emmagatzemar informació al client web i per recuperar-ne el contingut.
B24: d) S'han identificat i caracteritzat els mecanismes disponibles per a la autenticació dusuaris.
B25: e) S'han escrit aplicacions que integrin mecanismes d'autenticació usuaris.
B26: f) S'han utilitzat eines i entorns per facilitar la programació, prova i depuració del codi.
A27: RA5 | B27: a) S'han identificat els avantatges de separar la lògica de negoci dels aspectes de presentació de laplicació.
B28: b) S'han analitzat i utilitzat mecanismes i frameworks que permeten fer aquesta separació i les seves característiques principals.
B29: c) S'han utilitzat objectes i controls al servidor per generar l'aspecte visual de l'aplicació web al client.
B30: d) S'han utilitzat formularis generats de forma dinàmica per respondre als esdeveniments de laplicació web.
B31: e) S'han identificat i aplicat els paràmetres relatius a la configuració de l'aplicació web.
B32: f) S'han escrit aplicacions web amb manteniment d'estat i separació de la lògica de negoci.
A33: =IFERROR(VLOOKUP(B33,'4-CA'!$A$4:$B$105,2,FALSE),"") | B33: g) S'han aplicat els principis i patrons de disseny de la programació orientada a objectes.
B34: h) S'ha provat i documentat el codi.
A35: RA8 | B35: a) S'han identificat les diferències entre l'execució de codi al servidor i al client web.
B36: b) S'han reconegut els avantatges d'unir ambdues tecnologies en el procés desenvolupament de programes.
B37: c) S'han identificat les tecnologies i frameworks relacionades amb la generació per part del servidor de pàgines web amb guions encastats.
A38: =IFERROR(VLOOKUP(B38,'4-CA'!$A$4:$B$105,2,FALSE),"") | B38: d) S'han utilitzat aquestes tecnologies i frameworks per generar pàgines web que incloguin interacció amb l'usuari.
A39: =IFERROR(VLOOKUP(B39,'4-CA'!$A$4:$B$105,2,FALSE),"") | B39: e) S'han utilitzat aquestes tecnologies i frameworks, per generar pàgines web que incloguin verificació de formularis.
A40: =IFERROR(VLOOKUP(B40,'4-CA'!$A$4:$B$105,2,FALSE),"") | B40: f) S'han utilitzat aquestes tecnologies i frameworks per generar pàgines web que incloguin modificació dinàmica del contingut i l'estructura.
A41: =IFERROR(VLOOKUP(B41,'4-CA'!$A$4:$B$105,2,FALSE),"") | B41: g) S'han aplicat aquestes tecnologies i frameworks a la programació de aplicacions web.
...

Sheet UT5
A2: EMPLENAR CADA UNITAT DE TREBALL A UNA FULLA DIFERENT
A3: Unitat Treball | B3: ='6-Distribució temporal'!$A9 -> 5- | C3: HORES | D3: ='6-Distribució temporal'!$L9
A4: Criteris d'avaluació | C4: Continguts
A5: RA (RA1,...) | B5: Criteris d’avaluació
A7: =IFERROR(VLOOKUP(B7,'4-CA'!$A$4:$B$105,2,FALSE),"")
A8: =IFERROR(VLOOKUP(B8,'4-CA'!$A$4:$B$105,2,FALSE),"")
A9: =IFERROR(VLOOKUP(B9,'4-CA'!$A$4:$B$105,2,FALSE),"")
A10: =IFERROR(VLOOKUP(B10,'4-CA'!$A$4:$B$105,2,FALSE),"")
A11: =IFERROR(VLOOKUP(B11,'4-CA'!$A$4:$B$105,2,FALSE),"")
A12: =IFERROR(VLOOKUP(B12,'4-CA'!$A$4:$B$105,2,FALSE),"")
A13: =IFERROR(VLOOKUP(B13,'4-CA'!$A$4:$B$105,2,FALSE),"")
A14: =IFERROR(VLOOKUP(B14,'4-CA'!$A$4:$B$105,2,FALSE),"")
A15: Activitats d’ensenyament-aprenentatge (treballs, proves teòriques, proves pràctiques, exposicions, tasques...)
A16: Data | B16: Activitat | C16: Instrument avaluació * | D16: Seguiment**
A29: Observacions per introduir a la memòria final de curs (darrer full del document)
A30: Modificacions que consideres pel curs vinent, incidències, canvi del material i recursos didàctics emprats, millorar la coordinació amb altres mòduls, valoració dels criteris de qualificació, comportament del grup ...
A38: Fixau-vos que: - El títol de la Unitat de Treball i les hores s'emplenen automàticament de les dades introduïdes al full 6-Distribució temporal. - A l'apartat d'activitats d'ensenyament-aprenentatge: - Instrument d'avaluació*: pot ser una prova escrita, una rúbrica, una prova oral, un qüestionari, una pràctica, un treball... - Seguiment**: només s'ha d'emplenar si es fa servir el document com a QUADERN de professor, en tal cas, s'anotaran les incidències/observacions que es considerin oportunes.

Sheet UT6
A2: EMPLENAR CADA UNITAT DE TREBALL A UNA FULLA DIFERENT
A3: Unitat Treball | B3: ='6-Distribució temporal'!$A10 -> 6- | C3: HORES | D3: ='6-Distribució temporal'!$L10
A4: Criteris d'avaluació | C4: Continguts
A5: RA (RA1,...) | B5: Criteris d’avaluació
A7: =IFERROR(VLOOKUP(B7,'4-CA'!$A$4:$B$105,2,FALSE),"")
A8: =IFERROR(VLOOKUP(B8,'4-CA'!$A$4:$B$105,2,FALSE),"")
A9: =IFERROR(VLOOKUP(B9,'4-CA'!$A$4:$B$105,2,FALSE),"")
A10: =IFERROR(VLOOKUP(B10,'4-CA'!$A$4:$B$105,2,FALSE),"")
A11: =IFERROR(VLOOKUP(B11,'4-CA'!$A$4:$B$105,2,FALSE),"")
A12: =IFERROR(VLOOKUP(B12,'4-CA'!$A$4:$B$105,2,FALSE),"")
A13: =IFERROR(VLOOKUP(B13,'4-CA'!$A$4:$B$105,2,FALSE),"")
A14: =IFERROR(VLOOKUP(B14,'4-CA'!$A$4:$B$105,2,FALSE),"")
A15: Activitats d’ensenyament-aprenentatge (treballs, proves teòriques, proves pràctiques, exposicions, tasques...)
A16: Data | B16: Activitat | C16: Instrument avaluació * | D16: Seguiment**
A29: Observacions per introduir a la memòria final de curs (darrer full del document)
A30: Modificacions que consideres pel curs vinent, incidències, canvi del material i recursos didàctics emprats, millorar la coordinació amb altres mòduls, valoració dels criteris de qualificació, comportament del grup ...
A38: Fixau-vos que: - El títol de la Unitat de Treball i les hores s'emplenen automàticament de les dades introduïdes al full 6-Distribució temporal. - A l'apartat d'activitats d'ensenyament-aprenentatge: - Instrument d'avaluació*: pot ser una prova escrita, una rúbrica, una prova oral, un qüestionari, una pràctica, un treball... - Seguiment**: només s'ha d'emplenar si es fa servir el document com a QUADERN de professor, en tal cas, s'anotaran les incidències/observacions que es considerin oportunes.

Sheet UT7
A2: EMPLENAR CADA UNITAT DE TREBALL A UNA FULLA DIFERENT
A3: Unitat Treball | B3: ='6-Distribució temporal'!$A11 -> 7- | C3: HORES | D3: ='6-Distribució temporal'!$L11
A4: Criteris d'avaluació | C4: Continguts
A5: RA (RA1,...) | B5: Criteris d’avaluació
A7: =IFERROR(VLOOKUP(B7,'4-CA'!$A$4:$B$105,2,FALSE),"")
A8: =IFERROR(VLOOKUP(B8,'4-CA'!$A$4:$B$105,2,FALSE),"")
A9: =IFERROR(VLOOKUP(B9,'4-CA'!$A$4:$B$105,2,FALSE),"")
A10: =IFERROR(VLOOKUP(B10,'4-CA'!$A$4:$B$105,2,FALSE),"")
A11: =IFERROR(VLOOKUP(B11,'4-CA'!$A$4:$B$105,2,FALSE),"")
A12: =IFERROR(VLOOKUP(B12,'4-CA'!$A$4:$B$105,2,FALSE),"")
A13: =IFERROR(VLOOKUP(B13,'4-CA'!$A$4:$B$105,2,FALSE),"")
A14: =IFERROR(VLOOKUP(B14,'4-CA'!$A$4:$B$105,2,FALSE),"")
A15: Activitats d’ensenyament-aprenentatge (treballs, proves teòriques, proves pràctiques, exposicions, tasques...)
A16: Data | B16: Activitat | C16: Instrument avaluació * | D16: Seguiment**
A29: Observacions per introduir a la memòria final de curs (darrer full del document)
A30: Modificacions que consideres pel curs vinent, incidències, canvi del material i recursos didàctics emprats, millorar la coordinació amb altres mòduls, valoració dels criteris de qualificació, comportament del grup ...
A38: Fixau-vos que: - El títol de la Unitat de Treball i les hores s'emplenen automàticament de les dades introduïdes al full 6-Distribució temporal. - A l'apartat d'activitats d'ensenyament-aprenentatge: - Instrument d'avaluació*: pot ser una prova escrita, una rúbrica, una prova oral, un qüestionari, una pràctica, un treball... - Seguiment**: només s'ha d'emplenar si es fa servir el document com a QUADERN de professor, en tal cas, s'anotaran les incidències/observacions que es considerin oportunes.

Sheet UT8
A2: EMPLENAR CADA UNITAT DE TREBALL A UNA FULLA DIFERENT
A3: Unitat Treball | B3: ='6-Distribució temporal'!$A12 -> 8- | C3: HORES | D3: ='6-Distribució temporal'!$L12
A4: Criteris d'avaluació | C4: Continguts
A5: RA (RA1,...) | B5: Criteris d’avaluació
A7: =IFERROR(VLOOKUP(B7,'4-CA'!$A$4:$B$105,2,FALSE),"")
A8: =IFERROR(VLOOKUP(B8,'4-CA'!$A$4:$B$105,2,FALSE),"")
A9: =IFERROR(VLOOKUP(B9,'4-CA'!$A$4:$B$105,2,FALSE),"")
A10: =IFERROR(VLOOKUP(B10,'4-CA'!$A$4:$B$105,2,FALSE),"")
A11: =IFERROR(VLOOKUP(B11,'4-CA'!$A$4:$B$105,2,FALSE),"")
A12: =IFERROR(VLOOKUP(B12,'4-CA'!$A$4:$B$105,2,FALSE),"")
A13: =IFERROR(VLOOKUP(B13,'4-CA'!$A$4:$B$105,2,FALSE),"")
A14: =IFERROR(VLOOKUP(B14,'4-CA'!$A$4:$B$105,2,FALSE),"")
A15: Activitats d’ensenyament-aprenentatge (treballs, proves teòriques, proves pràctiques, exposicions, tasques...)
A16: Data | B16: Activitat | C16: Instrument avaluació * | D16: Seguiment**
A29: Observacions per introduir a la memòria final de curs (darrer full del document)
A30: Modificacions que consideres pel curs vinent, incidències, canvi del material i recursos didàctics emprats, millorar la coordinació amb altres mòduls, valoració dels criteris de qualificació, comportament del grup ...
A38: Fixau-vos que: - El títol de la Unitat de Treball i les hores s'emplenen automàticament de les dades introduïdes al full 6-Distribució temporal. - A l'apartat d'activitats d'ensenyament-aprenentatge: - Instrument d'avaluació*: pot ser una prova escrita, una rúbrica, una prova oral, un qüestionari, una pràctica, un treball... - Seguiment**: només s'ha d'emplenar si es fa servir el document com a QUADERN de professor, en tal cas, s'anotaran les incidències/observacions que es considerin oportunes.

Sheet UT9
A2: EMPLENAR CADA UNITAT DE TREBALL A UNA FULLA DIFERENT
A3: Unitat Treball | B3: ='6-Distribució temporal'!$A13 -> 9- | C3: HORES | D3: ='6-Distribució temporal'!$L13
A4: Criteris d'avaluació | C4: Continguts
A5: RA (RA1,...) | B5: Criteris d’avaluació
A7: =IFERROR(VLOOKUP(B7,'4-CA'!$A$4:$B$105,2,FALSE),"")
A8: =IFERROR(VLOOKUP(B8,'4-CA'!$A$4:$B$105,2,FALSE),"")
A9: =IFERROR(VLOOKUP(B9,'4-CA'!$A$4:$B$105,2,FALSE),"")
A10: =IFERROR(VLOOKUP(B10,'4-CA'!$A$4:$B$105,2,FALSE),"")
A11: =IFERROR(VLOOKUP(B11,'4-CA'!$A$4:$B$105,2,FALSE),"")
A12: =IFERROR(VLOOKUP(B12,'4-CA'!$A$4:$B$105,2,FALSE),"")
A13: =IFERROR(VLOOKUP(B13,'4-CA'!$A$4:$B$105,2,FALSE),"")
A14: =IFERROR(VLOOKUP(B14,'4-CA'!$A$4:$B$105,2,FALSE),"")
A15: Activitats d’ensenyament-aprenentatge (treballs, proves teòriques, proves pràctiques, exposicions, tasques...)
A16: Data | B16: Activitat | C16: Instrument avaluació * | D16: Seguiment**
A29: Observacions per introduir a la memòria final de curs (darrer full del document)
A30: Modificacions que consideres pel curs vinent, incidències, canvi del material i recursos didàctics emprats, millorar la coordinació amb altres mòduls, valoració dels criteris de qualificació, comportament del grup ...
A38: Fixau-vos que: - El títol de la Unitat de Treball i les hores s'emplenen automàticament de les dades introduïdes al full 6-Distribució temporal. - A l'apartat d'activitats d'ensenyament-aprenentatge: - Instrument d'avaluació*: pot ser una prova escrita, una rúbrica, una prova oral, un qüestionari, una pràctica, un treball... - Seguiment**: només s'ha d'emplenar si es fa servir el document com a QUADERN de professor, en tal cas, s'anotaran les incidències/observacions que es considerin oportunes.

Sheet UT10
A2: EMPLENAR CADA UNITAT DE TREBALL A UNA FULLA DIFERENT
A3: Unitat Treball | B3: ='6-Distribució temporal'!$A14 -> 10- | C3: HORES | D3: ='6-Distribució temporal'!$L14
A4: Criteris d'avaluació | C4: Continguts
A5: RA (RA1,...) | B5: Criteris d’avaluació
A7: =IFERROR(VLOOKUP(B7,'4-CA'!$A$4:$B$105,2,FALSE),"")
A8: =IFERROR(VLOOKUP(B8,'4-CA'!$A$4:$B$105,2,FALSE),"")
A9: =IFERROR(VLOOKUP(B9,'4-CA'!$A$4:$B$105,2,FALSE),"")
A10: =IFERROR(VLOOKUP(B10,'4-CA'!$A$4:$B$105,2,FALSE),"")
A11: =IFERROR(VLOOKUP(B11,'4-CA'!$A$4:$B$105,2,FALSE),"")
A12: =IFERROR(VLOOKUP(B12,'4-CA'!$A$4:$B$105,2,FALSE),"")
A13: =IFERROR(VLOOKUP(B13,'4-CA'!$A$4:$B$105,2,FALSE),"")
A14: =IFERROR(VLOOKUP(B14,'4-CA'!$A$4:$B$105,2,FALSE),"")
A15: Activitats d’ensenyament-aprenentatge (treballs, proves teòriques, proves pràctiques, exposicions, tasques...)
A16: Data | B16: Activitat | C16: Instrument avaluació * | D16: Seguiment**
A29: Observacions per introduir a la memòria final de curs (darrer full del document)
A30: Modificacions que consideres pel curs vinent, incidències, canvi del material i recursos didàctics emprats, millorar la coordinació amb altres mòduls, valoració dels criteris de qualificació, comportament del grup ...
A38: Fixau-vos que: - El títol de la Unitat de Treball i les hores s'emplenen automàticament de les dades introduïdes al full 6-Distribució temporal. - A l'apartat d'activitats d'ensenyament-aprenentatge: - Instrument d'avaluació*: pot ser una prova escrita, una rúbrica, una prova oral, un qüestionari, una pràctica, un treball... - Seguiment**: només s'ha d'emplenar si es fa servir el document com a QUADERN de professor, en tal cas, s'anotaran les incidències/observacions que es considerin oportunes.

Sheet UT11
A2: EMPLENAR CADA UNITAT DE TREBALL A UNA FULLA DIFERENT
A3: Unitat Treball | B3: ='6-Distribució temporal'!$A15 -> 11- | C3: HORES | D3: ='6-Distribució temporal'!$L15
A4: Criteris d'avaluació | C4: Continguts
A5: RA (RA1,...) | B5: Criteris d’avaluació
A7: =IFERROR(VLOOKUP(B7,'4-CA'!$A$4:$B$105,2,FALSE),"")
A8: =IFERROR(VLOOKUP(B8,'4-CA'!$A$4:$B$105,2,FALSE),"")
A9: =IFERROR(VLOOKUP(B9,'4-CA'!$A$4:$B$105,2,FALSE),"")
A10: =IFERROR(VLOOKUP(B10,'4-CA'!$A$4:$B$105,2,FALSE),"")
A11: =IFERROR(VLOOKUP(B11,'4-CA'!$A$4:$B$105,2,FALSE),"")
A12: =IFERROR(VLOOKUP(B12,'4-CA'!$A$4:$B$105,2,FALSE),"")
A13: =IFERROR(VLOOKUP(B13,'4-CA'!$A$4:$B$105,2,FALSE),"")
A14: =IFERROR(VLOOKUP(B14,'4-CA'!$A$4:$B$105,2,FALSE),"")
A15: Activitats d’ensenyament-aprenentatge (treballs, proves teòriques, proves pràctiques, exposicions, tasques...)
A16: Data | B16: Activitat | C16: Instrument avaluació * | D16: Seguiment**
A29: Observacions per introduir a la memòria final de curs (darrer full del document)
A30: Modificacions que consideres pel curs vinent, incidències, canvi del material i recursos didàctics emprats, millorar la coordinació amb altres mòduls, valoració dels criteris de qualificació, comportament del grup ...
A38: Fixau-vos que: - El títol de la Unitat de Treball i les hores s'emplenen automàticament de les dades introduïdes al full 6-Distribució temporal. - A l'apartat d'activitats d'ensenyament-aprenentatge: - Instrument d'avaluació*: pot ser una prova escrita, una rúbrica, una prova oral, un qüestionari, una pràctica, un treball... - Seguiment**: només s'ha d'emplenar si es fa servir el document com a QUADERN de professor, en tal cas, s'anotaran les incidències/observacions que es considerin oportunes.

Sheet UT12
A2: EMPLENAR CADA UNITAT DE TREBALL A UNA FULLA DIFERENT
A3: Unitat Treball | B3: ='6-Distribució temporal'!$A16 -> 12- | C3: HORES | D3: ='6-Distribució temporal'!$L16
A4: Criteris d'avaluació | C4: Continguts
A5: RA (RA1,...) | B5: Criteris d’avaluació
A7: =IFERROR(VLOOKUP(B7,'4-CA'!$A$4:$B$105,2,FALSE),"")
A8: =IFERROR(VLOOKUP(B8,'4-CA'!$A$4:$B$105,2,FALSE),"")
A9: =IFERROR(VLOOKUP(B9,'4-CA'!$A$4:$B$105,2,FALSE),"")
A10: =IFERROR(VLOOKUP(B10,'4-CA'!$A$4:$B$105,2,FALSE),"")
A11: =IFERROR(VLOOKUP(B11,'4-CA'!$A$4:$B$105,2,FALSE),"")
A12: =IFERROR(VLOOKUP(B12,'4-CA'!$A$4:$B$105,2,FALSE),"")
A13: =IFERROR(VLOOKUP(B13,'4-CA'!$A$4:$B$105,2,FALSE),"")
A14: =IFERROR(VLOOKUP(B14,'4-CA'!$A$4:$B$105,2,FALSE),"")
A15: Activitats d’ensenyament-aprenentatge (treballs, proves teòriques, proves pràctiques, exposicions, tasques...)
A16: Data | B16: Activitat | C16: Instrument avaluació * | D16: Seguiment**
A29: Observacions per introduir a la memòria final de curs (darrer full del document)
A30: Modificacions que consideres pel curs vinent, incidències, canvi del material i recursos didàctics emprats, millorar la coordinació amb altres mòduls, valoració dels criteris de qualificació, comportament del grup ...
A38: Fixau-vos que: - El títol de la Unitat de Treball i les hores s'emplenen automàticament de les dades introduïdes al full 6-Distribució temporal. - A l'apartat d'activitats d'ensenyament-aprenentatge: - Instrument d'avaluació*: pot ser una prova escrita, una rúbrica, una prova oral, un qüestionari, una pràctica, un treball... - Seguiment**: només s'ha d'emplenar si es fa servir el document com a QUADERN de professor, en tal cas, s'anotaran les incidències/observacions que es considerin oportunes.

Sheet MEMÒRIA FI DE CURS
A2: REVISIÓ DE LA PROGRAMACIÓ - MEMÒRIA FI DE CURS
A3: ASPECTES GENERALS
A4: Tot l'alumnat a excepció d'un va superar el mòdul. La prova diagnòstica inicial de programació va ser molt informativa, ja que precissament l'únic alumne que la va deixar buida va ser el que no va superar el mòdul. Malgrat el suport, duia massa endarreriment en programació.
A5: UNITAT DE TREBALL 1
A6: ='UT1'!A30 -> Modificacions que consideres pel curs vinent, incidències, canvi del material i recursos didàctics emprats, millorar la coordinació amb altres mòduls, valoració dels criteris de qualificació, comportament del grup ...
A13: UNITAT DE TREBALL 2
A14: ='UT2'!A30 -> Modificacions que consideres pel curs vinent, incidències, canvi del material i recursos didàctics emprats, millorar la coordinació amb altres mòduls, valoració dels criteris de qualificació, comportament del grup ...
A21: UNITAT DE TREBALL 3
A22: ='UT3'!A38 -> Modificacions que consideres pel curs vinent, incidències, canvi del material i recursos didàctics emprats, millorar la coordinació amb altres mòduls, valoració dels criteris de qualificació, comportament del grup ...
A29: UNITAT DE TREBALL 4
A30: ='UT4'!A60 -> Modificacions que consideres pel curs vinent, incidències, canvi del material i recursos didàctics emprats, millorar la coordinació amb altres mòduls, valoració dels criteris de qualificació, comportament del grup ...
A37: UNITAT DE TREBALL 5
A38: ='UT5'!A30 -> Modificacions que consideres pel curs vinent, incidències, canvi del material i recursos didàctics emprats, millorar la coordinació amb altres mòduls, valoració dels criteris de qualificació, comportament del grup ...
A45: UNITAT DE TREBALL 6
A46: ='UT6'!A30 -> Modificacions que consideres pel curs vinent, incidències, canvi del material i recursos didàctics emprats, millorar la coordinació amb altres mòduls, valoració dels criteris de qualificació, comportament del grup ...
A53: UNITAT DE TREBALL 7
A54: ='UT7'!A30 -> Modificacions que consideres pel curs vinent, incidències, canvi del material i recursos didàctics emprats, millorar la coordinació amb altres mòduls, valoració dels criteris de qualificació, comportament del grup ...
A61: UNITAT DE TREBALL 8
A62: ='UT8'!A30 -> Modificacions que consideres pel curs vinent, incidències, canvi del material i recursos didàctics emprats, millorar la coordinació amb altres mòduls, valoració dels criteris de qualificació, comportament del grup ...
A69: UNITAT DE TREBALL 9
A70: ='UT9'!A30 -> Modificacions que consideres pel curs vinent, incidències, canvi del material i recursos didàctics emprats, millorar la coordinació amb altres mòduls, valoració dels criteris de qualificació, comportament del grup ...
A77: UNITAT DE TREBALL 10
A78: ='UT10'!A30 -> Modificacions que consideres pel curs vinent, incidències, canvi del material i recursos didàctics emprats, millorar la coordinació amb altres mòduls, valoració dels criteris de qualificació, comportament del grup ...
A85: UNITAT DE TREBALL 11
A86: ='UT11'!A30 -> Modificacions que consideres pel curs vinent, incidències, canvi del material i recursos didàctics emprats, millorar la coordinació amb altres mòduls, valoració dels criteris de qualificació, comportament del grup ...
A93: UNITAT DE TREBALL 12
A94: ='UT12'!A30 -> Modificacions que consideres pel curs vinent, incidències, canvi del material i recursos didàctics emprats, millorar la coordinació amb altres mòduls, valoració dels criteris de qualificació, comportament del grup ...
